<?xml version="1.0" ?>
<robot name="fruit_harvester" xmlns:xacro="http://www.ros.org/wiki/xacro">

<xacro:include filename="$(find fruit_harvester_description)/urdf/materials.xacro" />
<xacro:include filename="$(find fruit_harvester_description)/urdf/fruit_harvester.trans" />
<xacro:include filename="$(find fruit_harvester_description)/urdf/fruit_harvester.gazebo" />
<link name="base_link">
  <inertial>
    <origin xyz="-2.141483605028195e-16 -3.6379137549613626e-17 0.0040000000000000105" rpy="0 0 0"/>
    <mass value="14.300000000000002"/>
    <inertia ixx="0.297993" iyy="0.297993" izz="0.595833" ixy="0.0" iyz="0.0" ixz="-0.0"/>
  </inertial>
  <visual>
    <origin xyz="0 0 0" rpy="0 0 0"/>
    <geometry>
      <mesh filename="package://fruit_harvester_description/meshes/base_link.stl" scale="0.001 0.001 0.001"/>
    </geometry>
    <material name="silver"/>
  </visual>
  <collision>
    <origin xyz="0 0 0" rpy="0 0 0"/>
    <geometry>
      <mesh filename="package://fruit_harvester_description/meshes/base_link.stl" scale="0.001 0.001 0.001"/>
    </geometry>
  </collision>
</link>

<link name="holder__1">
  <inertial>
    <origin xyz="5.5951482468685754e-06 2.1636982916017898e-06 0.021279248953684275" rpy="0 0 0"/>
    <mass value="14.078041686781889"/>
    <inertia ixx="0.123973" iyy="0.12451" izz="0.212985" ixy="2e-06" iyz="1e-06" ixz="2e-06"/>
  </inertial>
  <visual>
    <origin xyz="0.0 0.0 -0.008" rpy="0 0 0"/>
    <geometry>
      <mesh filename="package://fruit_harvester_description/meshes/holder__1.stl" scale="0.001 0.001 0.001"/>
    </geometry>
    <material name="silver"/>
  </visual>
  <collision>
    <origin xyz="0.0 0.0 -0.008" rpy="0 0 0"/>
    <geometry>
      <mesh filename="package://fruit_harvester_description/meshes/holder__1.stl" scale="0.001 0.001 0.001"/>
    </geometry>
  </collision>
</link>

<link name="grip2_1">
  <inertial>
    <origin xyz="0.05396121204712789 -0.021775092276819213 0.0041358607672603714" rpy="0 0 0"/>
    <mass value="0.08498904911563737"/>
    <inertia ixx="3.8e-05" iyy="0.000276" izz="0.000312" ixy="7.8e-05" iyz="2e-06" ixz="-4e-06"/>
  </inertial>
  <visual>
    <origin xyz="-0.937708 0.02428 -0.113813" rpy="0 0 0"/>
    <geometry>
      <mesh filename="package://fruit_harvester_description/meshes/grip2_1.stl" scale="0.001 0.001 0.001"/>
    </geometry>
    <material name="silver"/>
  </visual>
  <collision>
    <origin xyz="-0.937708 0.02428 -0.113813" rpy="0 0 0"/>
    <geometry>
      <mesh filename="package://fruit_harvester_description/meshes/grip2_1.stl" scale="0.001 0.001 0.001"/>
    </geometry>
  </collision>
</link>

<link name="grip1_1">
  <inertial>
    <origin xyz="0.05659943776932308 0.024051327350246596 0.0041777012711190775" rpy="0 0 0"/>
    <mass value="0.2152423048382853"/>
    <inertia ixx="0.000112" iyy="0.000682" izz="0.000789" ixy="-0.000222" iyz="-5e-06" ixz="-1e-05"/>
  </inertial>
  <visual>
    <origin xyz="-0.937708 -0.02972 -0.113813" rpy="0 0 0"/>
    <geometry>
      <mesh filename="package://fruit_harvester_description/meshes/grip1_1.stl" scale="0.001 0.001 0.001"/>
    </geometry>
    <material name="silver"/>
  </visual>
  <collision>
    <origin xyz="-0.937708 -0.02972 -0.113813" rpy="0 0 0"/>
    <geometry>
      <mesh filename="package://fruit_harvester_description/meshes/grip1_1.stl" scale="0.001 0.001 0.001"/>
    </geometry>
  </collision>
</link>

<link name="cam_1">
  <inertial>
    <origin xyz="-0.12698645894426208 -1.2721445784870749 1.5528924739410601" rpy="0 0 0"/>
    <mass value="0.32739564469380616"/>
    <inertia ixx="0.000252" iyy="2.4e-05" izz="0.00025" ixy="2e-06" iyz="-0.0" ixz="0.0"/>
  </inertial>
  <visual>
    <origin xyz="-0.957888 -1.274 1.387915" rpy="0 0 0"/>
    <geometry>
      <mesh filename="package://fruit_harvester_description/meshes/cam_1.stl" scale="0.001 0.001 0.001"/>
    </geometry>
    <material name="silver"/>
  </visual>
  <collision>
    <origin xyz="-0.957888 -1.274 1.387915" rpy="0 0 0"/>
    <geometry>
      <mesh filename="package://fruit_harvester_description/meshes/cam_1.stl" scale="0.001 0.001 0.001"/>
    </geometry>
  </collision>
</link>

<link name="link_3_1">
  <inertial>
    <origin xyz="0.02290017157246893 0.027591903501862174 0.0028196018260233657" rpy="0 0 0"/>
    <mass value="1.2255204125736512"/>
    <inertia ixx="0.001242" iyy="0.00165" izz="0.001516" ixy="-1.1e-05" iyz="-1e-06" ixz="4e-06"/>
  </inertial>
  <visual>
    <origin xyz="-0.799979 0.02595 -0.115442" rpy="0 0 0"/>
    <geometry>
      <mesh filename="package://fruit_harvester_description/meshes/link_3_1.stl" scale="0.001 0.001 0.001"/>
    </geometry>
    <material name="silver"/>
  </visual>
  <collision>
    <origin xyz="-0.799979 0.02595 -0.115442" rpy="0 0 0"/>
    <geometry>
      <mesh filename="package://fruit_harvester_description/meshes/link_3_1.stl" scale="0.001 0.001 0.001"/>
    </geometry>
  </collision>
</link>

<link name="link_1_1">
  <inertial>
    <origin xyz="0.2046453317718992 0.04905444059427562 -0.00037314149269021546" rpy="0 0 0"/>
    <mass value="8.14858833077929"/>
    <inertia ixx="0.022502" iyy="0.25306" izz="0.261723" ixy="0.002387" iyz="0.000318" ixz="0.001677"/>
  </inertial>
  <visual>
    <origin xyz="-0.0 0.04995 -0.12" rpy="0 0 0"/>
    <geometry>
      <mesh filename="package://fruit_harvester_description/meshes/link_1_1.stl" scale="0.001 0.001 0.001"/>
    </geometry>
    <material name="silver"/>
  </visual>
  <collision>
    <origin xyz="-0.0 0.04995 -0.12" rpy="0 0 0"/>
    <geometry>
      <mesh filename="package://fruit_harvester_description/meshes/link_1_1.stl" scale="0.001 0.001 0.001"/>
    </geometry>
  </collision>
</link>

<link name="grip_base_1">
  <inertial>
    <origin xyz="0.07309602472061638 0.0015701009657076359 -0.004053852003403288" rpy="0 0 0"/>
    <mass value="0.7312652454578921"/>
    <inertia ixx="0.00038" iyy="0.000942" izz="0.001299" ixy="4.1e-05" iyz="-2e-06" ixz="5.1e-05"/>
  </inertial>
  <visual>
    <origin xyz="-0.859887 -0.00205 -0.11212" rpy="0 0 0"/>
    <geometry>
      <mesh filename="package://fruit_harvester_description/meshes/grip_base_1.stl" scale="0.001 0.001 0.001"/>
    </geometry>
    <material name="silver"/>
  </visual>
  <collision>
    <origin xyz="-0.859887 -0.00205 -0.11212" rpy="0 0 0"/>
    <geometry>
      <mesh filename="package://fruit_harvester_description/meshes/grip_base_1.stl" scale="0.001 0.001 0.001"/>
    </geometry>
  </collision>
</link>

<link name="link_2_1">
  <inertial>
    <origin xyz="0.32088016597361724 1.2310345562914609 -0.404781120786467" rpy="0 0 0"/>
    <mass value="3.724745482250577"/>
    <inertia ixx="0.004679" iyy="0.04153" izz="0.042556" ixy="-0.000331" iyz="4e-06" ixz="9.1e-05"/>
  </inertial>
  <visual>
    <origin xyz="-0.338859 1.232001 -0.520021" rpy="0 0 0"/>
    <geometry>
      <mesh filename="package://fruit_harvester_description/meshes/link_2_1.stl" scale="0.001 0.001 0.001"/>
    </geometry>
    <material name="silver"/>
  </visual>
  <collision>
    <origin xyz="-0.338859 1.232001 -0.520021" rpy="0 0 0"/>
    <geometry>
      <mesh filename="package://fruit_harvester_description/meshes/link_2_1.stl" scale="0.001 0.001 0.001"/>
    </geometry>
  </collision>
</link>

<joint name="Rev179" type="continuous">
  <origin xyz="0.0 0.0 0.008" rpy="0 0 0"/>
  <parent link="base_link"/>
  <child link="holder__1"/>
  <axis xyz="-0.0 0.0 1.0"/>
</joint>

<joint name="Rev192" type="continuous">
  <origin xyz="0.077821 -0.02633 0.001693" rpy="0 0 0"/>
  <parent link="grip_base_1"/>
  <child link="grip2_1"/>
  <axis xyz="-0.055374 0.0 -0.998466"/>
</joint>

<joint name="Rev193" type="continuous">
  <origin xyz="0.077821 0.02767 0.001693" rpy="0 0 0"/>
  <parent link="grip_base_1"/>
  <child link="grip1_1"/>
  <axis xyz="-0.055374 0.0 -0.998466"/>
</joint>

<joint name="Rigid199" type="fixed">
  <origin xyz="0.157909 1.29995 -1.503357" rpy="0 0 0"/>
  <parent link="link_3_1"/>
  <child link="cam_1"/>
</joint>

<joint name="Rev200" type="continuous">
  <origin xyz="0.46112 1.206051 -0.404579" rpy="0 0 0"/>
  <parent link="link_2_1"/>
  <child link="link_3_1"/>
  <axis xyz="-0.0 1.0 0.0"/>
</joint>

<joint name="Rev202" type="continuous">
  <origin xyz="0.0 -0.04995 0.112" rpy="0 0 0"/>
  <parent link="holder__1"/>
  <child link="link_1_1"/>
  <axis xyz="0.0 1.0 0.0"/>
</joint>

<joint name="Rigid203" type="fixed">
  <origin xyz="0.059908 0.028 -0.003322" rpy="0 0 0"/>
  <parent link="link_3_1"/>
  <child link="grip_base_1"/>
</joint>

<joint name="Rev204" type="continuous">
  <origin xyz="0.338859 -1.182051 0.400021" rpy="0 0 0"/>
  <parent link="link_1_1"/>
  <child link="link_2_1"/>
  <axis xyz="-0.0 -1.0 -0.0"/>
</joint>

</robot>
