<?xml version="1.0" ?>
<robot name="fruit_harvester" xmlns:xacro="http://www.ros.org/wiki/xacro">

<xacro:include filename="$(find fruit_harvester_description)/urdf/materials.xacro" />
<xacro:include filename="$(find fruit_harvester_description)/urdf/fruit_harvester.trans" />
<xacro:include filename="$(find fruit_harvester_description)/urdf/fruit_harvester.gazebo" />
<xacro:include filename="$(find fruit_harvester_description)/urdf/cam_plugin.urdf.xacro" />
<link name="base_link">
  <inertial>
    <origin xyz="-2.1414836050281949e-16 -3.6379137549613626e-17 0.00400000000000001" rpy="0 0 0"/>
    <mass value="5.4"/>
    <inertia ixx="0.112529" iyy="0.112529" izz="0.225" ixy="0.0" iyz="0.0" ixz="-0.0"/>
  </inertial>
  <visual>
    <origin xyz="0 0 0" rpy="0 0 0"/>
    <geometry>
      <mesh filename="package://fruit_harvester_description/meshes/base_link.stl" scale="0.001 0.001 0.001"/>
    </geometry>
    <material name="silver"/>
  </visual>
  <collision>
    <origin xyz="0 0 0" rpy="0 0 0"/>
    <geometry>
      <mesh filename="package://fruit_harvester_description/meshes/base_link.stl" scale="0.001 0.001 0.001"/>
    </geometry>
  </collision>
</link>

<link name="link_3_1">
  <inertial>
    <origin xyz="0.058725159105752045 0.033728041106190806 -0.034281954180965024" rpy="0 0 0"/>
    <mass value="0.6942959033045424"/>
    <inertia ixx="0.001171" iyy="0.002877" izz="0.002397" ixy="-1.1e-05" iyz="6e-06" ixz="0.001086"/>
  </inertial>
  <visual>
    <origin xyz="-0.232711 0.05495 -0.885405" rpy="0 0 0"/>
    <geometry>
      <mesh filename="package://fruit_harvester_description/meshes/link_3_1.stl" scale="0.001 0.001 0.001"/>
    </geometry>
    <material name="silver"/>
  </visual>
  <collision>
    <origin xyz="-0.232711 0.05495 -0.885405" rpy="0 0 0"/>
    <geometry>
      <mesh filename="package://fruit_harvester_description/meshes/link_3_1.stl" scale="0.001 0.001 0.001"/>
    </geometry>
  </collision>
</link>

<link name="link_2_1">
  <inertial>
    <origin xyz="0.04673875878358216 -0.02501644370807371 0.15277019193192154" rpy="0 0 0"/>
    <mass value="1.4065472450456722"/>
    <inertia ixx="0.014837" iyy="0.015683" izz="0.003" ixy="-3.8e-05" iyz="-0.000119" ixz="-0.004015"/>
  </inertial>
  <visual>
    <origin xyz="-0.145308 0.06295 -0.59842" rpy="0 0 0"/>
    <geometry>
      <mesh filename="package://fruit_harvester_description/meshes/link_2_1.stl" scale="0.001 0.001 0.001"/>
    </geometry>
    <material name="silver"/>
  </visual>
  <collision>
    <origin xyz="-0.145308 0.06295 -0.59842" rpy="0 0 0"/>
    <geometry>
      <mesh filename="package://fruit_harvester_description/meshes/link_2_1.stl" scale="0.001 0.001 0.001"/>
    </geometry>
  </collision>
</link>

<link name="link_1_1">
  <inertial>
    <origin xyz="0.05983014347595997 0.049054440594274905 0.19570438161226295" rpy="0 0 0"/>
    <mass value="3.0770892997348365"/>
    <inertia ixx="0.090851" iyy="0.095561" izz="0.016479" ixy="0.000147" iyz="0.000897" ixz="-0.025646"/>
  </inertial>
  <visual>
    <origin xyz="-0.0 0.04995 -0.12" rpy="0 0 0"/>
    <geometry>
      <mesh filename="package://fruit_harvester_description/meshes/link_1_1.stl" scale="0.001 0.001 0.001"/>
    </geometry>
    <material name="silver"/>
  </visual>
  <collision>
    <origin xyz="-0.0 0.04995 -0.12" rpy="0 0 0"/>
    <geometry>
      <mesh filename="package://fruit_harvester_description/meshes/link_1_1.stl" scale="0.001 0.001 0.001"/>
    </geometry>
  </collision>
</link>

<link name="grip2_1">
  <inertial>
    <origin xyz="0.42881475174315176 -1.284949999999971 1.983868241058124" rpy="0 0 0"/>
    <mass value="0.038880000000000005"/>
    <inertia ixx="1.3e-05" iyy="4.7e-05" izz="3.5e-05" ixy="0.0" iyz="0.0" ixz="2e-05"/>
  </inertial>
  <visual>
    <origin xyz="-0.017955 -1.274 1.223446" rpy="0 0 0"/>
    <geometry>
      <mesh filename="package://fruit_harvester_description/meshes/grip2_1.stl" scale="0.001 0.001 0.001"/>
    </geometry>
    <material name="silver"/>
  </visual>
  <collision>
    <origin xyz="-0.017955 -1.274 1.223446" rpy="0 0 0"/>
    <geometry>
      <mesh filename="package://fruit_harvester_description/meshes/grip2_1.stl" scale="0.001 0.001 0.001"/>
    </geometry>
  </collision>
</link>

<link name="grip1_1">
  <inertial>
    <origin xyz="0.4288147517431557 -1.304949999999973 1.9838682410581254" rpy="0 0 0"/>
    <mass value="0.038880000000000005"/>
    <inertia ixx="1.3e-05" iyy="4.7e-05" izz="3.5e-05" ixy="0.0" iyz="0.0" ixz="2e-05"/>
  </inertial>
  <visual>
    <origin xyz="-0.017955 -1.274 1.223446" rpy="0 0 0"/>
    <geometry>
      <mesh filename="package://fruit_harvester_description/meshes/grip1_1.stl" scale="0.001 0.001 0.001"/>
    </geometry>
    <material name="silver"/>
  </visual>
  <collision>
    <origin xyz="-0.017955 -1.274 1.223446" rpy="0 0 0"/>
    <geometry>
      <mesh filename="package://fruit_harvester_description/meshes/grip1_1.stl" scale="0.001 0.001 0.001"/>
    </geometry>
  </collision>
</link>

<link name="cam_1">
  <inertial>
    <origin xyz="0.005352108700830527 -0.0001540506804192758 0.01065725767265735" rpy="0 0 0"/>
    <mass value="0.32739564469380406"/>
    <inertia ixx="0.000251" iyy="2.4e-05" izz="0.00025" ixy="-8e-06" iyz="5e-06" ixz="-1e-06"/>
  </inertial>
  <visual>
    <origin xyz="-0.302859 0.02095 -0.890767" rpy="0 0 0"/>
    <geometry>
      <mesh filename="package://fruit_harvester_description/meshes/cam_1.stl" scale="0.001 0.001 0.001"/>
    </geometry>
    <material name="silver"/>
  </visual>
  <collision>
    <origin xyz="-0.302859 0.02095 -0.890767" rpy="0 0 0"/>
    <geometry>
      <mesh filename="package://fruit_harvester_description/meshes/cam_1.stl" scale="0.001 0.001 0.001"/>
    </geometry>
  </collision>
</link>
<link name="camera_link_optical">
</link>
<joint name="camera_optical_link" type="fixed">
  <parent link="cam_1"/>
  <child link="camera_link_optical"/>
  <origin xyz="0.0 0.0 0.0" rpy="-1.57079632679 0.0 -1.57079632679"/>
</joint>
<link name="holder__1">
  <inertial>
    <origin xyz="5.59514824743701e-06 2.163698291495209e-06 0.0212792489536842" rpy="0 0 0"/>
    <mass value="5.316183574029524"/>
    <inertia ixx="0.046815" iyy="0.047018" izz="0.080428" ixy="1e-06" iyz="0.0" ixz="1e-06"/>
  </inertial>
  <visual>
    <origin xyz="0.0 0.0 -0.008" rpy="0 0 0"/>
    <geometry>
      <mesh filename="package://fruit_harvester_description/meshes/holder__1.stl" scale="0.001 0.001 0.001"/>
    </geometry>
    <material name="silver"/>
  </visual>
  <collision>
    <origin xyz="0.0 0.0 -0.008" rpy="0 0 0"/>
    <geometry>
      <mesh filename="package://fruit_harvester_description/meshes/holder__1.stl" scale="0.001 0.001 0.001"/>
    </geometry>
  </collision>
</link>

<joint name="Rev157" type="continuous">
  <origin xyz="0.087403 0.008 0.286985" rpy="0 0 0"/>
  <parent link="link_2_1"/>
  <child link="link_3_1"/>
  <axis xyz="-0.0 1.0 -0.0"/>
</joint>

<joint name="Rev167" type="continuous">
  <origin xyz="0.145308 -0.013 0.47842" rpy="0 0 0"/>
  <parent link="link_1_1"/>
  <child link="link_2_1"/>
  <axis xyz="-0.0 1.0 -0.0"/>
</joint>

<joint name="Rev168" type="continuous">
  <origin xyz="0.0 -0.04995 0.112" rpy="0 0 0"/>
  <parent link="holder__1"/>
  <child link="link_1_1"/>
  <axis xyz="0.0 1.0 0.0"/>
</joint>

<joint name="Slider175" type="prismatic">
  <origin xyz="-0.214756 1.32895 -2.108851" rpy="0 0 0"/>
  <parent link="link_3_1"/>
  <child link="grip2_1"/>
  <axis xyz="0.0 -1.0 0.0"/>
  <limit upper="0.0" lower="0.0" effort="100" velocity="100"/>
</joint>

<joint name="Slider176" type="prismatic">
  <origin xyz="-0.214756 1.32895 -2.108851" rpy="0 0 0"/>
  <parent link="link_3_1"/>
  <child link="grip1_1"/>
  <axis xyz="0.0 -1.0 0.0"/>
  <limit upper="0.0" lower="0.0" effort="100" velocity="100"/>
</joint>

<joint name="Rigid178" type="fixed">
  <origin xyz="0.070148 0.034 0.005362" rpy="0 0 0"/>
  <parent link="link_3_1"/>
  <child link="cam_1"/>
</joint>

<joint name="Rev179" type="continuous">
  <origin xyz="0.0 0.0 0.008" rpy="0 0 0"/>
  <parent link="base_link"/>
  <child link="holder__1"/>
  <axis xyz="-0.0 0.0 1.0"/>
</joint>

</robot>